2025-10-15 14:00:29,827 INFO    MainThread:6370 [wandb_setup.py:_flush():81] Current SDK version is 0.22.0
2025-10-15 14:00:29,827 INFO    MainThread:6370 [wandb_setup.py:_flush():81] Configure stats pid to 6370
2025-10-15 14:00:29,827 INFO    MainThread:6370 [wandb_setup.py:_flush():81] Loading settings from /Users/husazwerg/.config/wandb/settings
2025-10-15 14:00:29,827 INFO    MainThread:6370 [wandb_setup.py:_flush():81] Loading settings from /Users/husazwerg/code/gitlab.fhnw.ch/michelle.rohrer/Deep_Learning/wandb/settings
2025-10-15 14:00:29,827 INFO    MainThread:6370 [wandb_setup.py:_flush():81] Loading settings from environment variables
2025-10-15 14:00:29,827 INFO    MainThread:6370 [wandb_init.py:setup_run_log_directory():686] Logging user logs to /Users/husazwerg/code/gitlab.fhnw.ch/michelle.rohrer/Deep_Learning/wandb/run-20251015_140029-38h5uu8o/logs/debug.log
2025-10-15 14:00:29,828 INFO    MainThread:6370 [wandb_init.py:setup_run_log_directory():687] Logging internal logs to /Users/husazwerg/code/gitlab.fhnw.ch/michelle.rohrer/Deep_Learning/wandb/run-20251015_140029-38h5uu8o/logs/debug-internal.log
2025-10-15 14:00:29,828 INFO    MainThread:6370 [wandb_init.py:monkeypatch_ipython():605] configuring jupyter hooks <wandb.sdk.wandb_init._WandbInit object at 0x12ab56ff0>
2025-10-15 14:00:29,828 INFO    MainThread:6370 [wandb_init.py:init():813] calling init triggers
2025-10-15 14:00:29,828 INFO    MainThread:6370 [wandb_init.py:init():818] wandb.init called with sweep_config: {}
config: {'learning_rate': 0.01, 'batch_size': 64, 'num_epochs': 200, 'optimizer': 'SGD', 'momentum': 0, 'architecture': 'BaselineCNN', 'dataset': 'FER-2013', '_wandb': {}}
2025-10-15 14:00:29,828 INFO    MainThread:6370 [wandb_init.py:init():861] starting backend
2025-10-15 14:00:30,081 INFO    MainThread:6370 [wandb_init.py:init():864] sending inform_init request
2025-10-15 14:00:30,129 INFO    MainThread:6370 [wandb_init.py:init():872] backend started and connected
2025-10-15 14:00:30,137 INFO    MainThread:6370 [wandb_run.py:_label_probe_notebook():1330] probe notebook
2025-10-15 14:00:30,141 INFO    MainThread:6370 [wandb_init.py:init():942] updated telemetry
2025-10-15 14:00:30,213 INFO    MainThread:6370 [wandb_init.py:init():966] communicating run to backend with 90.0 second timeout
2025-10-15 14:00:30,766 INFO    MainThread:6370 [wandb_init.py:init():1017] starting run threads in backend
2025-10-15 14:00:31,086 INFO    MainThread:6370 [wandb_run.py:_console_start():2506] atexit reg
2025-10-15 14:00:31,087 INFO    MainThread:6370 [wandb_run.py:_redirect():2354] redirect: wrap_raw
2025-10-15 14:00:31,087 INFO    MainThread:6370 [wandb_run.py:_redirect():2423] Wrapping output streams.
2025-10-15 14:00:31,088 INFO    MainThread:6370 [wandb_run.py:_redirect():2446] Redirects installed.
2025-10-15 14:00:31,094 INFO    MainThread:6370 [wandb_init.py:init():1057] run started, returning control to user process
2025-10-15 14:49:55,330 INFO    wandb-AsyncioManager-main:6370 [service_client.py:_forward_responses():84] Reached EOF.
2025-10-15 14:49:55,370 INFO    wandb-AsyncioManager-main:6370 [mailbox.py:close():137] Closing mailbox, abandoning 1 handles.
2025-10-15 14:49:57,772 INFO    MainThread:6370 [wandb_init.py:_post_run_cell_hook():575] [no run ID] resuming backend
2025-10-15 14:49:57,774 ERROR   wandb-AsyncioManager-main:6370 [asyncio_manager.py:fn_wrap_exceptions():183] [no run ID] Uncaught exception in run_soon callback.
Traceback (most recent call last):
  File "/Users/husazwerg/code/gitlab.fhnw.ch/michelle.rohrer/Deep_Learning/.venv/lib/python3.12/site-packages/wandb/sdk/lib/asyncio_manager.py", line 181, in fn_wrap_exceptions
    await fn()
  File "/Users/husazwerg/code/gitlab.fhnw.ch/michelle.rohrer/Deep_Learning/.venv/lib/python3.12/site-packages/wandb/sdk/lib/service/service_client.py", line 65, in _send_server_request
    await self._writer.drain()
  File "/Library/Frameworks/Python.framework/Versions/3.12/lib/python3.12/asyncio/streams.py", line 392, in drain
    await self._protocol._drain_helper()
  File "/Library/Frameworks/Python.framework/Versions/3.12/lib/python3.12/asyncio/streams.py", line 166, in _drain_helper
    raise ConnectionResetError('Connection lost')
ConnectionResetError: Connection lost
